Workbook

Sheet Análisis de precios
A4: CLIENTE: | B4: ANALISIS DE PRECIO GENERAL TRABAJO EN ALTURA
A5: OBRA: | B5: TRABAJOS EN ALTURA-MO Y MAT - PINO SOLUCIONES TECNICAS
A6: FECHA: | B6: 45910
A7: CONTACTO: | B7: PINO SOLUCIONES TECNICAS
A8: ANÁLISIS DE PRECIOS
A10: RUBRO | B10: ÍTEM | C10: DENOMINACIÓN | D10: UNIDAD | E10: CANTIDAD | G10: PRECIO UNITARIO | H10: PRECIO PARCIAL | I10: PRECIO RUBRO | K10: % ITEM | L10: % RUBRO | N10: Cantidad parcial | O10: Precio unitario | P10: Precio parcial
B11: 1.1. | C11: PINTURA EXTERIOR EN ALTURA | D11: M2 | E11: 5250 | G11: =SUM(G12:G22) -> 7003.3929 | H11: =G11*E11 -> 36767812 | I11: =+H11/E11 -> 7003.3929 | Q11: PERSONAS | R11: DIAS TOT | S11: DIAS DE TRABAJO
A12: MO | C12: Oficial en altura | D12: hs | E12: 0.33 | F12: 8780 | G12: =+E12*F12 -> 2897.4 | N12: =E12*$E$11 -> 1732.5 | O12: =+F12 -> 8780 | P12: =N12*O12 -> 15211350 | Q12: 6 | R12: =+N12/8 -> 216.5625 | S12: =+R12/Q12 -> 36.09375
A13: MO | C13: Ayudante | D13: hs | E13: 0.15 | F13: 5619 | G13: =+E13*F13 -> 842.85 | N13: =E13*$E$11 -> 787.5 | O13: =+F13 -> 5619 | P13: =N13*O13 -> 4424962.5 | Q13: 3 | R13: =+N13/8 -> 98.4375 | S13: =+R13/Q13 -> 32.8125
A14: MAT | B14: 110041 | C14: Lija al agua Nro 80 | D14: U | E14: =80/E11 -> 0.015238095 | F14: 900 | G14: =+E14*F14 -> 13.714286 | N14: =E14*$E$11 -> 80 | O14: =+F14 -> 900 | P14: =N14*O14 -> 72000
A15: MAT | B15: 110240 | C15: Viruta de acero fina x 300 grs | D15: U | E15: =40/E11 -> 0.0076190476 | F15: 1000 | G15: =+E15*F15 -> 7.6190476 | N15: =E15*$E$11 -> 40 | O15: =+F15 -> 1000 | P15: =N15*O15 -> 40000
A16: MAT | B16: 110020 | C16: Fijador al agua x 1 lt | D16: lts | E16: 0.1 | F16: 3000 | G16: =+E16*F16 -> 300 | N16: =E16*$E$11 -> 525 | O16: =+F16 -> 3000 | P16: =N16*O16 -> 1575000
A17: MAT | B17: 109031 | C17: BERSELL BLANCO x 1KG. | D17: kg | E17: =80/E11 -> 0.015238095 | F17: 6900 | G17: =+E17*F17 -> 105.14286 | N17: =E17*$E$11 -> 80 | O17: =+F17 -> 6900 | P17: =N17*O17 -> 552000
A18: MAT | B18: 110314 | C18: Duralba Impermeab Exterior BLANCO x 1 lt | D18: lts | E18: 0.4 | F18: 6850 | G18: =+E18*F18 -> 2740 | N18: =E18*$E$11 -> 2100 | O18: =+F18 -> 6850 | P18: =N18*O18 -> 14385000
A19: MAT | B19: 110090 | C19: Pinceleta Nro 40 | D19: U | E19: =15/E11 -> 0.0028571429 | F19: 1100 | G19: =+E19*F19 -> 3.1428571 | N19: =E19*$E$11 -> 15 | O19: =+F19 -> 1100 | P19: =N19*O19 -> 16500
A20: MAT | B20: 110062 | C20: Rodillo antigota 20 cm | D20: U | E20: =30/E11 -> 0.0057142857 | F20: 4500 | G20: =+E20*F20 -> 25.714286 | N20: =E20*$E$11 -> 30 | O20: =+F20 -> 4500 | P20: =N20*O20 -> 135000
A21: MAT | B21: 110112 | C21: Poximix EXTERIOR x 1,25 kg | D21: bolsa | E21: =25/E11 -> 0.0047619048 | F21: 13500 | G21: =+E21*F21 -> 64.285714 | N21: =E21*$E$11 -> 25 | O21: =+F21 -> 13500 | P21: =N21*O21 -> 337500
A22: MAT | C22: Film polietileno negro 200 micrones (2x50 m) | D22: rollo | E22: =0.5/E11 -> 9.5238095e-05 | F22: 37000 | G22: =+E22*F22 -> 3.5238095 | N22: =E22*$E$11 -> 0.5 | O22: =+F22 -> 37000 | P22: =N22*O22 -> 18500
H23: =SUM(H11:H21) -> 36767812 | P23: =SUM(P11:P22) -> 36767812

Sheet Cascada
C2: SACAR PERMISO PARA USO DE VEREDA
A4: CLIENTE: | B4: Karina D' Antiochia Administradora KD
A5: OBRA: | B5: TRABAJOS EN ALTURA-MO Y MAT - SAN MARTIN 353 - CORRIENTES CAPITAL
A6: FECHA: | B6: 45917
A7: CONTACTO: | B7: ADM KARINA - TEL : 3794 33-1270
A8: ANÁLISIS DE PRECIOS
A10: RUBRO | B10: ITEM | C10: DENOMINACION | D10: UNIDAD | E10: CANTIDAD | F10: PRECIO UNIT SIN IVA | G10: PRECIO PARCIAL SIN IVA
A11: 1 | C11: COSTO - COSTO | G11: =SUM(G12:G14) -> 36749312
A12: 1 | B12: 1 | C12: MATERIALES | D12: GL | E12: 1 | F12: =SUMIF('Análisis de precios'!$A$9:$A$21,"MAT",'Análisis de precios'!$P$9:$P$21) -> 17113000 | G12: =+E12*F12 -> 17113000 | H12: =+G12/$G$84 -> 0.22545338 | I12: =+G12/$I$84 -> 0.24912599 | J12: 4932974.4
A13: 1 | B13: 2 | C13: MANO DE OBRA | D13: GL | E13: 1 | F13: =SUMIF('Análisis de precios'!$A$9:$A$21,"MO",'Análisis de precios'!$P$9:$P$21) -> 19636312 | G13: =+E13*F13 -> 19636312 | H13: =+G13/$G$84 -> 0.25869649 | I13: =+G13/$I$84 -> 0.28585963
A14: 1 | B14: 3 | C14: EQUIPOS | D14: GL | E14: 1 | F14: =SUMIF('Análisis de precios'!$A$9:$A$12,"EQUIPOS",'Análisis de precios'!$P$9:$P$12) -> 0 | G14: =+E14*F14 -> 0
A16: 2 | C16: GASTOS GENERALES DIRECTOS | G16: =SUM(G17:G61) -> 3316788 | H16: =+G16/$G$84 -> 0.043696668
C17: Sueldos / Honorarios de Dirección de Obra | D17: Mes | E17: 1 | F17: 1350000 | G17: =E17*F17 -> 1350000
C18: Viáticos de Dirección de Obra | D18: Dia | E18: 0 | F18: 50000 | G18: =E18*F18 -> 0
C19: Alojamiento para Dirección de Obra | D19: Dia | E19: 0 | F19: 5000 | G19: =E19*F19 -> 0
C20: Combustible para movilidad de Dirección de Obra | D20: Km | E20: 300 | F20: 125 | G20: =E20*F20 -> 37500
C21: Mantenimiento vehicular de Dirección de Obra | D21: Km | E21: 300 | F21: 125 | G21: =E21*F21 -> 37500
C22: Pasajes para Dirección de Obra | D22: U | E22: 0 | F22: 0 | G22: =E22*F22 -> 0
C23: Gastos varios de movilidad -Estacionamiento, peajes, etc- | D23: GL | E23: 0 | F23: 0 | G23: =E23*F23 -> 0
C24: Librería | D24: GL | E24: 0 | F24: 0 | G24: =E24*F24 -> 0
C25: Seguros para Dirección de Obra | D25: Mes | E25: 1 | F25: 18000 | G25: =E25*F25 -> 18000
C26: Indumentaria y EPP para Dirección de Obra | D26: JUEGO | E26: 0.166 | F26: 85000 | G26: =E26*F26 -> 14110
G27: =E27*F27 -> 0
C28: Viáticos del personal operativo | D28: DIA | E28: 0 | F28: 0 | G28: =E28*F28 -> 0
C29: Alojamiento para personal operativo | D29: DIA | E29: 0 | F29: 0 | G29: =E29*F29 -> 0
C30: Combustible para movilidad de personal operativo | D30: KM | E30: 0 | F30: 0 | G30: =E30*F30 -> 0
C31: Mantenimiento vehicular para personal operativo | D31: KM | E31: 0 | F31: 0 | G31: =E31*F31 -> 0
C32: Pasajes para personal operativo | D32: U | E32: 0 | F32: 1000 | G32: =E32*F32 -> 0
C33: Gastos varios de movilidad -Estacionamiento, peajes, etc- | D33: GL | E33: 0 | F33: 0 | G33: =E33*F33 -> 0
C34: Seguros para el personal operativo | D34: MES | E34: 4 | F34: 18000 | G34: =E34*F34 -> 72000
C35: Indumentaria y EPP para el personal operativo | D35: JUEGO | E35: 2 | F35: 85000 | G35: =E35*F35 -> 170000
C37: Programa de Higiene y Seguridad | D37: GL | E37: 4 | F37: 160000 | G37: =E37*F37 -> 640000
C38: Permiso de obra | D38: DIA | E38: 0 | F38: 35000 | G38: =E38*F38 -> 0
C39: Sueldos / Honorarios de Resposable de Higiene y Seguridad | D39: GL | E39: 1 | F39: 800000 | G39: =E39*F39 -> 800000
C40: Gastos administrativos | D40: GL | E40: 0 | F40: 600000 | G40: =E40*F40 -> 0
... C48: Gastos varios de movilidad -Estacionamiento, peajes, etc- | D48: GL | E48: 0 | F48: 0 | G48: =E48*F48 -> 0
C49: Impuesto al cheque | D49: GL | E49: 0.006 | F49: =F12 -> 17113000 | G49: =E49*F49 -> 102678
C50: Gastos administrativos | D50: GL | E50: 0 | F50: 1000000 | G50: =E50*F50 -> 0
C51: Sueldo / Honorarios de Pañolero | D51: MES | E51: 0 | F51: 0 | G51: =E51*F51 -> 0
C52: Viáticos de Pañolero | D52: DIA | E52: 0 | F52: 0 | G52: =E52*F52 -> 0
...

Sheet Precio
A4: CLIENTE: | B4: ANALISIS DE PRECIO GENERAL TRABAJO EN ALTURA
A5: OBRA: | B5: TRABAJOS EN ALTURA-MO Y MAT - PINO SOLUCIONES TECNICAS
A6: FECHA: | B6: 45910
A7: CONTACTO: | B7: PINO SOLUCIONES TECNICAS
A8: ANÁLISIS DE PRECIOS
A10: RUBRO | B10: ÍTEM | C10: DENOMINACIÓN | D10: UNIDAD | E10: CANTIDAD | F10: PRECIO UNITARIO | G10: PRECIO PARCIAL
B11: 1.1. | C11: PINTURA EXTERIOR EN ALTURA | D11: M2 | E11: 4860 | F11: ='Análisis de precios'!G11*Cascada!H84 -> 14465.341 | G11: =F11*E11 -> 70301555
F12: TOTAL | G12: =SUM(G11:G11) -> 70301555
A13: DESCRIPCIÓN TÉCNICA DEL SERVICIO – PINTURA EXTERIOR DE EDIFICIO
A14: Objeto: Provisión de equipamiento, materiales , mano de obra especializada y asesoramiento comercial sin cargo, para la ejecución integral de pintura exterior en altura.
A15: 1. PREPARACIÓN DE SUPERFICIES
A16: Limpieza y saneamiento de las fachadas a intervenir, eliminando elementos contaminantes (polvo, polvo orgánico, pintura descascarada u otros residuos), en zonas donde sean necesarias.
A17: Inspección detallada de fisuras y grietas visibles que puedan comprometer la integridad superficial.
A18: 2. SELLADO
A19: Aplicación de sellador elastomérico de alta flexibilidad sobre fisuras detectadas, asegurando impermeabilidad y adaptación a leves movimientos estructurales.
A20: 3. IMPRIMACIÓN
A21: Aplicación de una mano de fijador acrílico profesional al agua, que homogeneiza la absorción del soporte y mejora la adherencia del acabado final.
A22: 4. PINTURA LATEX EXTERIOR ( DURALBA FRENTE Y MUROS - COLOR A ELECCION DEL CLIENTE)
A23: Aplicación de dos manos de pintura látex DURALBA , garantizando superficie uniforme y resistencia frente al desgaste climático.
A24: 5. ÁMBITO DE INTERVENCIÓN
... A35: Nota: El presente presupuesto contiene impuestos -

Sheet Programa de trabajo
A4: CLIENTE: | B4: Karina D' Antiochia Administradora KD
A5: OBRA: | B5: TRABAJOS EN ALTURA-MO Y MAT - SAN LUIS 699 - EDIF ANTARES III - CORRIENTES CAPITAL
A6: FECHA: | B6: 45929
A7: CONTACTO: | B7: ADM KARINA - TEL : 3794 33-1270
A8: ANÁLISIS DE PRECIOS
A10: RUBRO | B10: ÍTEM | C10: DENOMINACIÓN | D10: UNIDAD | E10: CANTIDAD | F10: 26 DIAS
B11: 1.1. | C11: PINTURA EXTERIOR EN ALTURA | D11: M2 | E11: 2459
A13: DESCRIPCIÓN TÉCNICA DEL SERVICIO – PINTURA EXTERIOR DE EDIFICIO
A14: Objeto: Provisión de equipamiento, materiales , mano de obra especializada y asesoramiento comercial sin cargo, para la ejecución integral de pintura exterior en altura.
A15: 1. PREPARACIÓN DE SUPERFICIES
A16: Limpieza y saneamiento de las fachadas a intervenir, eliminando elementos contaminantes (polvo, polvo orgánico, pintura descascarada u otros residuos), en zonas donde sean necesarias.
A17: Inspección detallada de fisuras y grietas visibles que puedan comprometer la integridad superficial.
A18: 2. SELLADO
A19: Aplicación de sellador elastomérico de alta flexibilidad sobre fisuras detectadas, asegurando impermeabilidad y adaptación a leves movimientos estructurales.
A20: 3. IMPRIMACIÓN
A21: Aplicación de una mano de fijador acrílico profesional al agua, que homogeneiza la absorción del soporte y mejora la adherencia del acabado final.
A22: 4. PINTURA LATEX EXTERIOR ( DURALBA FRENTE Y MUROS - COLOR A ELECCION DEL CLIENTE)
A23: Aplicación de dos manos de pintura látex DURALBA , garantizando superficie uniforme y resistencia frente al desgaste climático.
A24: 5. ÁMBITO DE INTERVENCIÓN
... A39: Sin reajustes ni modificaciones al precio acordado.

Sheet Insumos
A4: CLIENTE: | B4: ANALISIS DE PRECIO GENERAL TRABAJO EN ALTURA
A5: OBRA: | B5: TRABAJOS EN ALTURA-MO Y MAT - PINO SOLUCIONES TECNICAS
A6: FECHA: | B6: 45910
A7: CONTACTO: | B7: PINO SOLUCIONES TECNICAS
A8: ANÁLISIS DE PRECIOS
A10: RUBRO | B10: ÍTEM | C10: DENOMINACIÓN | D10: UNIDAD | E10: CANTIDAD | G10: PRECIO UNITARIO
A11: MO | C11: Oficial en altura | D11: hs | E11: =SUMIF('Análisis de precios'!C10:P21,C11,'Análisis de precios'!N10:$N$21) -> 1732.5 | F11: 6601.61 | G11: =+E11*F11 -> 11437289
A12: MO | C12: Ayudante | D12: hs | E12: =SUMIF('Análisis de precios'!C11:P23,C12,'Análisis de precios'!N11:$N$21) -> 787.5 | F12: 5000 | G12: =+E12*F12 -> 3937500
A13: MAT | B13: 110041 | C13: Lija al agua Nro 80 | D13: U | E13: =SUMIF('Análisis de precios'!C12:P24,C13,'Análisis de precios'!N12:$N$21) -> 80 | F13: 900 | G13: =+E13*F13 -> 72000
A14: MAT | B14: 110240 | C14: Viruta de acero fina x 300 grs | D14: U | E14: =SUMIF('Análisis de precios'!C13:P25,C14,'Análisis de precios'!N13:$N$21) -> 40 | F14: 1000 | G14: =+E14*F14 -> 40000
A15: MAT | B15: 110020 | C15: Fijador al agua x 1 lt | D15: lts | E15: =SUMIF('Análisis de precios'!C14:P26,C15,'Análisis de precios'!N14:$N$21) -> 525 | F15: 3000 | G15: =+E15*F15 -> 1575000
A16: MAT | B16: 109031 | C16: BERSELL BLANCO x 1KG. | D16: kg | E16: =SUMIF('Análisis de precios'!C15:P27,C16,'Análisis de precios'!N15:$N$21) -> 80 | F16: 6900 | G16: =+E16*F16 -> 552000
A17: MAT | B17: 110314 | C17: Duralba Impermeab Exterior BLANCO x 1 lt | D17: lts | E17: =SUMIF('Análisis de precios'!C16:P28,C17,'Análisis de precios'!N16:$N$21) -> 2100 | F17: 6850 | G17: =+E17*F17 -> 14385000
A18: MAT | B18: 110090 | C18: Pinceleta Nro 40 | D18: U | E18: =SUMIF('Análisis de precios'!C17:P29,C18,'Análisis de precios'!N17:$N$21) -> 15 | F18: 1100 | G18: =+E18*F18 -> 16500
A19: MAT | B19: 110062 | C19: Rodillo antigota 20 cm | D19: U | E19: =SUMIF('Análisis de precios'!C18:P30,C19,'Análisis de precios'!N18:$N$21) -> 30 | F19: 4500 | G19: =+E19*F19 -> 135000
A20: MAT | B20: 110112 | C20: Poximix EXTERIOR x 1,25 kg | D20: bolsa | E20: =SUMIF('Análisis de precios'!C19:P31,C20,'Análisis de precios'!N19:$N$21) -> 25 | F20: 13500 | G20: =+E20*F20 -> 337500
C21: Film polietileno negro 200 micrones (2x50 m) | D21: rollo | E21: =SUMIF('Análisis de precios'!C20:P32,C21,'Análisis de precios'!N20:$N$21) -> 0.5 | F21: 37000 | G21: =+E21*F21 -> 18500
F22: TOTAL | G22: =SUM(G11:G21) -> 32506289
