Workbook

Sheet Análisis de precios
A4: CLIENTE: | B4: ANALISIS DE PRECIO GENERAL CON LA PINTURA INTERIOR DE PINO
A5: OBRA: | B5: TRABAJOS INTERIOR DE PINTURA EN ESCALERA (PAREDES Y PISOS) Y PINTURA SINTETICA EN BARANDAS
A6: FECHA: | B6: 45940
A7: CONTACTO: | B7: PINO SOLUCIONES TECNICAS
A8: ANÁLISIS DE PRECIOS
A10: RUBRO | B10: ÍTEM | C10: DENOMINACIÓN | D10: UNIDAD | E10: CANTIDAD | G10: PRECIO UNITARIO | H10: PRECIO PARCIAL | I10: PRECIO RUBRO | K10: % ITEM | L10: % RUBRO | N10: Cantidad parcial | O10: Precio unitario | P10: Precio parcial
B11: 1.1. | C11: APLICACIÓN DE PINTURA LATEX EN INTERIOR PAREDES ESCALERA | D11: M2 | E11: 8800 | G11: =SUM(G12:G19) -> 6153.3096 | H11: =G11*E11 -> 54149125 | Q11: PERSONAS | R11: DIAS TOT | S11: DIAS DE TRABAJO
A12: MO | C12: Oficial a nivel | D12: hs | E12: =8/15 -> 0.53333333 | F12: 4409 | G12: =+E12*F12 -> 2351.4667 | N12: =E12*$E$11 -> 4693.3333 | O12: =+F12 -> 4409 | P12: =N12*O12 -> 20692907 | Q12: 7 | R12: =+N12/8 -> 586.66667 | S12: =+R12/Q12 -> 83.809524
A13: MAT | B13: 110041 | C13: Lija al agua Nro 80 | D13: U | E13: 0.01 | F13: 800 | G13: =+E13*F13 -> 8 | N13: =E13*$E$11 -> 88 | O13: =+F13 -> 800 | P13: =N13*O13 -> 70400
A14: MAT | B14: 110020 | C14: Fijador al agua x 1 lt | D14: lts | E14: 0.1 | F14: =4000/1.21 -> 3305.7851 | G14: =+E14*F14 -> 330.57851 | N14: =E14*$E$11 -> 880 | O14: =+F14 -> 3305.7851 | P14: =N14*O14 -> 2909090.9
A15: MAT | B15: 110317 | C15: Albalatex Interior BLANCO x 1 lt | D15: lts | E15: 0.25 | F15: 6850 | G15: =+E15*F15 -> 1712.5 | N15: =E15*$E$11 -> 2200 | O15: =+F15 -> 6850 | P15: =N15*O15 -> 15070000 | S15: =S12+#REF! -> #REF!
A16: MAT | B16: 110090 | C16: Pinceleta Nro 40 | D16: U | E16: =1/800 -> 0.00125 | F16: 2100 | G16: =+E16*F16 -> 2.625 | N16: =E16*$E$11 -> 11 | O16: =+F16 -> 2100 | P16: =N16*O16 -> 23100
A17: MAT | B17: 110062 | C17: Rodillo antigota 20 cm | D17: U | E17: =1/400 -> 0.0025 | F17: 4200 | G17: =+E17*F17 -> 10.5 | N17: =E17*$E$11 -> 22 | O17: =+F17 -> 4200 | P17: =N17*O17 -> 92400
A18: MAT | B18: 110351 | C18: Enduido Plástico x 1 kg | D18: kg | E18: 0.6 | F18: =3500/1.21 -> 2892.562 | G18: =+E18*F18 -> 1735.5372 | N18: =E18*$E$11 -> 5280 | O18: =+F18 -> 2892.562 | P18: =N18*O18 -> 15272727
A19: MAT | C19: Film polietileno negro 200 micrones (2x50 m) | D19: rollo | E19: =0.5/E11 -> 5.6818182e-05 | F19: 37000 | G19: =+E19*F19 -> 2.1022727 | N19: =E19*$E$11 -> 0.5 | O19: =+F19 -> 37000 | P19: =N19*O19 -> 18500
H20: =SUM(H11:H17) -> 54149125 | P20: =SUM(P11:P19) -> 54149125

Sheet Cascada
A4: CLIENTE: | B4: =+'Análisis de precios'!B4 -> ANALISIS DE PRECIO GENERAL CON LA PINTURA INTERIOR DE PINO
A5: OBRA: | B5: =+'Análisis de precios'!B5 -> TRABAJOS INTERIOR DE PINTURA EN ESCALERA (PAREDES Y PISOS) Y PINTURA SINTETICA EN BARANDAS
A6: FECHA: | B6: =+'Análisis de precios'!B6 -> 45940
A7: CONTACTO: | B7: =+'Análisis de precios'!B7 -> PINO SOLUCIONES TECNICAS
A8: ANÁLISIS DE PRECIOS
A10: RUBRO | B10: ITEM | C10: DENOMINACION | D10: UNIDAD | E10: CANTIDAD | F10: PRECIO UNIT SIN IVA | G10: PRECIO PARCIAL SIN IVA
A11: 1 | C11: COSTO - COSTO | G11: =SUM(G12:G14) -> 54149125
A12: 1 | B12: 1 | C12: MATERIALES | D12: GL | E12: 1 | F12: =SUMIF('Análisis de precios'!$A$9:$A$20,"MAT",'Análisis de precios'!$P$9:$P$20) -> 33456218 | G12: =+E12*F12 -> 33456218 | H12: =+G12/$G$84 -> 0.30397576 | I12: =+G12/$I$84 -> 0.33589322 | J12: 4932974.4
A13: 1 | B13: 2 | C13: MANO DE OBRA | D13: GL | E13: 1 | F13: =SUMIF('Análisis de precios'!$A$9:$A$20,"MO",'Análisis de precios'!$P$9:$P$20) -> 20692907 | G13: =+E13*F13 -> 20692907 | H13: =+G13/$G$84 -> 0.18801115 | I13: =+G13/$I$84 -> 0.20775232
A14: 1 | B14: 3 | C14: EQUIPOS | D14: GL | E14: 1 | F14: =SUMIF('Análisis de precios'!$A$9:$A$12,"EQUIPOS",'Análisis de precios'!$P$9:$P$12) -> 0 | G14: =+E14*F14 -> 0
A16: 2 | C16: GASTOS GENERALES DIRECTOS | G16: =SUM(G17:G61) -> 3946787.3 | H16: =G16/G11 -> 0.07288737
C17: Sueldos / Honorarios de Dirección de Obra | D17: Mes | E17: 2 | F17: 1350000 | G17: =E17*F17 -> 2700000
C18: Viáticos de Dirección de Obra | D18: Dia | E18: 0 | F18: 50000 | G18: =E18*F18 -> 0
C19: Alojamiento para Dirección de Obra | D19: Dia | E19: 0 | F19: 5000 | G19: =E19*F19 -> 0
C20: Combustible para movilidad de Dirección de Obra | D20: Km | E20: 550 | F20: 200 | G20: =E20*F20 -> 110000
C21: Mantenimiento vehicular de Dirección de Obra | D21: Km | E21: 550 | F21: 200 | G21: =E21*F21 -> 110000
C22: Pasajes para Dirección de Obra | D22: U | E22: 0 | F22: 0 | G22: =E22*F22 -> 0
C23: Gastos varios de movilidad -Estacionamiento, peajes, etc- | D23: GL | E23: 0 | F23: 0 | G23: =E23*F23 -> 0
C24: Librería | D24: GL | E24: 0 | F24: 0 | G24: =E24*F24 -> 0
C25: Seguros para Dirección de Obra | D25: Mes | E25: 2 | F25: 18000 | G25: =E25*F25 -> 36000
C26: Indumentaria y EPP para Dirección de Obra | D26: JUEGO | E26: 0.33 | F26: 85000 | G26: =E26*F26 -> 28050
G27: =E27*F27 -> 0
C28: Viáticos del personal operativo | D28: DIA | E28: 0 | F28: 0 | G28: =E28*F28 -> 0
C29: Alojamiento para personal operativo | D29: DIA | E29: 0 | F29: 0 | G29: =E29*F29 -> 0
C30: Combustible para movilidad de personal operativo | D30: KM | E30: 0 | F30: 0 | G30: =E30*F30 -> 0
C31: Mantenimiento vehicular para personal operativo | D31: KM | E31: 0 | F31: 0 | G31: =E31*F31 -> 0
C32: Pasajes para personal operativo | D32: U | E32: 0 | F32: 1000 | G32: =E32*F32 -> 0
C33: Gastos varios de movilidad -Estacionamiento, peajes, etc- | D33: GL | E33: 0 | F33: 0 | G33: =E33*F33 -> 0
C34: Seguros para el personal operativo | D34: MES | E34: =7*78/25 -> 21.84 | F34: 15000 | G34: =E34*F34 -> 327600
C35: Indumentaria y EPP para el personal operativo | D35: JUEGO | E35: =(7*78/25)/6 -> 3.64 | F35: 85000 | G35: =E35*F35 -> 309400
C37: Programa de Higiene y Seguridad | D37: GL | E37: 0 | F37: 160000 | G37: =E37*F37 -> 0
C38: Permiso de obra | D38: DIA | E38: 0 | F38: 30000 | G38: =E38*F38 -> 0
C39: Sueldos / Honorarios de Resposable de Higiene y Seguridad | D39: GL | E39: 0 | F39: 300000 | G39: =E39*F39 -> 0
C40: Elementos de señalización | D40: GL | E40: 0 | F40: 15000 | G40: =E40*F40 -> 0
C42: Fletes de materiales | D42: KM | E42: 0 | F42: 0 | G42: =E42*F42 -> 0
C43: Viáticos de chóferes | D43: DIA | E43: 0 | F43: 0 | G43: =E43*F43 -> 0
C44: Alojamiento de chóferes | D44: DIA | E44: 0 | F44: 0 | G44: =E44*F44 -> 0
C45: Combustible para movilidad de personal operativo | D45: KM | E45: 500 | F45: 125 | G45: =E45*F45 -> 62500
C46: Mantenimiento vehicular para personal de compras | D46: KM | E46: 500 | F46: 125 | G46: =E46*F46 -> 62500
C47: Pasajes para personal de compras | D47: GL | E47: 0 | F47: 0 | G47: =E47*F47 -> 0
...

Sheet Precio
A4: CLIENTE: | B4: ANALISIS DE PRECIO GENERAL CON LA PINTURA INTERIOR DE PINO
A5: OBRA: | B5: TRABAJOS INTERIOR DE PINTURA EN ESCALERA (PAREDES Y PISOS) Y PINTURA SINTETICA EN BARANDAS
A6: FECHA: | B6: 45940
A7: CONTACTO: | B7: PINO SOLUCIONES TECNICAS
A8: ANÁLISIS DE PRECIOS
A10: RUBRO | B10: ÍTEM | C10: DENOMINACIÓN | D10: UNIDAD | E10: CANTIDAD | F10: PRECIO UNITARIO | G10: PRECIO PARCIAL
B11: 1.1. | C11: APLICACIÓN DE PINTURA LATEX EN INTERIOR PAREDES ESCALERA | D11: M2 | E11: 8800 | F11: ='Análisis de precios'!G11*Cascada!H84 -> 12507.06 | G11: =F11*E11 -> 1.1006212e+08
F12: TOTAL | G12: =SUM(G11:G11) -> 1.1006212e+08
A13: DESCRIPCIÓN DE LOS TRABAJOS A REALIZAR
A14: Objeto del servicio:
A15: Provisión de mano de obra especializada para la ejecución de trabajos de pintura interior en el sector de escalera del edificio.
A16: Áreas a intervenir:
A17: Cielorrasos del sector de escalera.
A18: Paredes interiores del sector mencionado.
A19: Observaciones:
A20: Quedan expresamente excluidos de este presupuesto los siguientes elementos:
A21: Pintura de barandas.
A22: Pisos y/o peldaños de las escaleras.
A23: Puertas de acceso a los pisos.
A24: Alcance de los trabajos:
... A27: Aplicación de manos de pintura látex para interiores, hasta alcanzar un acabado uniforme, prolijo y de buena terminación estética.

Sheet Programa de trabajo
A4: CLIENTE: | B4: ANALISIS DE PRECIO GENERAL CON LA PINTURA INTERIOR DE PINO
A5: OBRA: | B5: TRABAJOS INTERIOR DE PINTURA EN ESCALERA (PAREDES Y PISOS) Y PINTURA SINTETICA EN BARANDAS
A6: FECHA: | B6: 45940
A7: CONTACTO: | B7: PINO SOLUCIONES TECNICAS
A8: ANÁLISIS DE PRECIOS
A10: RUBRO | B10: ÍTEM | C10: DENOMINACIÓN | D10: UNIDAD | E10: CANTIDAD | F10: 78 DIAS
B11: 1.1. | C11: APLICACIÓN DE PINTURA LATEX EN INTERIOR PAREDES ESCALERA | D11: M2 | E11: 8800

Sheet Insumos
A4: CLIENTE: | B4: ANALISIS DE PRECIO GENERAL CON LA PINTURA INTERIOR DE PINO
A5: OBRA: | B5: TRABAJOS INTERIOR DE PINTURA EN ESCALERA (PAREDES Y PISOS) Y PINTURA SINTETICA EN BARANDAS
A6: FECHA: | B6: 45940
A7: CONTACTO: | B7: PINO SOLUCIONES TECNICAS
A8: ANÁLISIS DE PRECIOS
A10: RUBRO | B10: ÍTEM | C10: DENOMINACIÓN | D10: UNIDAD | E10: CANTIDAD | G10: PRECIO UNITARIO
A11: MO | C11: Oficial a nivel | D11: hs | E11: =SUMIF('Análisis de precios'!C10:P17,C11,'Análisis de precios'!N10:$N$17) -> 4693.3333 | F11: 4409 | G11: =+E11*F11 -> 20692907
A12: MAT | B12: 110041 | C12: Lija al agua Nro 80 | D12: U | E12: =SUMIF('Análisis de precios'!C11:P20,C12,'Análisis de precios'!N11:$N$17) -> 88 | F12: 800 | G12: =+E12*F12 -> 70400
A13: MAT | B13: 110020 | C13: Fijador al agua x 1 lt | D13: lts | E13: =SUMIF('Análisis de precios'!C12:P21,C13,'Análisis de precios'!N12:$N$17) -> 880 | F13: =4000/1.21 -> 3305.7851 | G13: =+E13*F13 -> 2909090.9
A14: MAT | B14: 110317 | C14: Albalatex Interior BLANCO x 1 lt | D14: lts | E14: =SUMIF('Análisis de precios'!C14:P23,C14,'Análisis de precios'!N14:$N$17) -> 2200 | F14: 6850 | G14: =+E14*F14 -> 15070000
A15: MAT | B15: 110090 | C15: Pinceleta Nro 40 | D15: U | E15: =SUMIF('Análisis de precios'!C15:P24,C15,'Análisis de precios'!N15:$N$17) -> 11 | F15: 2100 | G15: =+E15*F15 -> 23100
A16: MAT | B16: 110062 | C16: Rodillo antigota 20 cm | D16: U | E16: =SUMIF('Análisis de precios'!C15:P25,C16,'Análisis de precios'!N15:$N$17) -> 22 | F16: 4200 | G16: =+E16*F16 -> 92400
A17: MAT | B17: 110351 | C17: Enduido Plástico x 1 kg | D17: kg | E17: =SUMIF('Análisis de precios'!C16:P26,C17,'Análisis de precios'!N16:$N$17) -> 5280 | F17: =3500/1.21 -> 2892.562 | G17: =+E17*F17 -> 15272727
A18: MAT | C18: Film polietileno negro 200 micrones (2x50 m) | D18: rollo | E18: =SUMIF('Análisis de precios'!C17:P27,C18,'Análisis de precios'!N17:$N$17) -> 0.5 | F18: 37000 | G18: =+E18*F18 -> 18500
F19: TOTAL | G19: =SUM(G11:G18) -> 54149125
