Workbook

Sheet Análisis de precios
A4: CLIENTE | B4: ANALISIS GENRAL DE PRECIOS POLIURETANO - PINO SOLUCIONES TECNICAS
A5: OBRA: | B5: APLICACIÓN DE ESPUMA DE POLIURETANO - MENSUAL DE PINO
A6: FECHA: | B6: 45940
A7: CONTACTO: | B7: PINO SOLUCUIONES TECNICAS
A8: ANÁLISIS DE PRECIOS
A10: RUBRO | B10: ÍTEM | C10: DENOMINACIÓN | D10: UNIDAD | E10: CANTIDAD | G10: PRECIO UNITARIO | H10: PRECIO PARCIAL | I10: PRECIO RUBRO | K10: % ITEM | L10: % RUBRO | N10: Cantidad parcial | O10: Precio unitario | P10: Precio parcial
B11: 2.1. | C11: APLICACIÓN DE ESPUMA DE POLIURETANO EN TODA LA SUPERFICIE | D11: M2 | E11: 1096 | G11: =SUM(G12:G15) -> 9512.7335 | H11: =+E11*G11 -> 10425956 | Q11: PERSONAS | R11: DIAS | S11: DIAS DE TRABAJO
A12: MO | C12: Oficial aplicador | D12: hs | E12: =48/E11 -> 0.04379562 | F12: 7224.61 | G12: =+E12*F12 -> 316.40628 | N12: =E12*$E$11 -> 48 | O12: =+F12 -> 7224.61 | P12: =N12*O12 -> 346781.28 | Q12: 1 | R12: =+N12/8 -> 6 | S12: =+R12/Q12 -> 6
A13: MO | C13: Ayudante | D13: hs | E13: =96/E11 -> 0.087591241 | F13: 5000 | G13: =+E13*F13 -> 437.9562 | N13: =E13*$E$11 -> 96 | O13: =+F13 -> 5000 | P13: =N13*O13 -> 480000 | Q13: 1 | R13: =+N13/8 -> 12 | S13: =+R13/Q13 -> 12
A14: MAT | B14: 101001 | C14: Espuma Poliuretano POLIRESINAS x kg | D14: Kg | E14: 1.25 | F14: =5*1400 -> 7000 | G14: =+E14*F14 -> 8750 | N14: =E14*$E$11 -> 1370 | O14: =+F14 -> 7000 | P14: =N14*O14 -> 9590000
A15: MAT | C15: Film polietileno negro 200 micrones (2x50 m) | D15: rollo | E15: 0.00022624434 | F15: 37000 | G15: =+E15*F15 -> 8.3710407 | N15: =E15*$E$11 -> 0.2479638 | O15: =+F15 -> 37000 | P15: =N15*O15 -> 9174.6606
H16: =SUM(H11:H15) -> 10425956 | P16: =SUM(P12:P15) -> 10425956

Sheet Cascada
A4: CLIENTE | B4: ANALISIS GENRAL DE PRECIOS POLIURETANO - PINO SOLUCIONES TECNICAS
A5: OBRA: | B5: APLICACIÓN DE ESPUMA DE POLIURETANO - MENSUAL DE PINO
A6: FECHA: | B6: 45940
A7: CONTACTO: | B7: PINO SOLUCUIONES TECNICAS
A8: ANÁLISIS DE PRECIOS
A10: RUBRO | B10: ITEM | C10: DENOMINACION | D10: UNIDAD | E10: dias | F10: CANTIDAD | G10: PRECIO UNIT SIN IVA | H10: PRECIO PARCIAL SIN IVA
A11: 1 | C11: COSTO - COSTO | H11: =SUM(H12:H14) -> 10425956
A12: 1 | B12: 1 | C12: MATERIALES | D12: GL | F12: 1 | G12: =SUMIF('Análisis de precios'!$A$9:$A$15,"MAT",'Análisis de precios'!$P$9:$P$14) -> 9599174.7 | H12: =+F12*G12 -> 9599174.7
A13: 1 | B13: 2 | C13: MANO DE OBRA | D13: GL | F13: 1 | G13: =SUMIF('Análisis de precios'!$A$9:$A$14,"MO",'Análisis de precios'!$P$9:$P$14) -> 826781.28 | H13: =+F13*G13 -> 826781.28
A14: 1 | B14: 3 | C14: EQUIPOS | D14: GL | F14: 1 | G14: =SUMIF('Análisis de precios'!$A$9:$A$10,"EQUIPOS",'Análisis de precios'!$P$9:$P$10) -> 0 | H14: =+F14*G14 -> 0
A16: 2 | C16: GASTOS GENERALES DIRECTOS | H16: =SUM(H17:H60) -> 1063395
C17: Sueldos / Honorarios de Dirección de Obra | D17: Mes | F17: 0.24 | G17: 1650000 | H17: =F17*G17 -> 396000
C18: Viáticos de Dirección de Obra | D18: Dia | F18: 0 | G18: 12000 | H18: =F18*G18 -> 0
C19: Alojamiento para Dirección de Obra | D19: Dia | F19: 0 | G19: 40000 | H19: =F19*G19 -> 0
C20: Combustible para movilidad de Dirección de Obra | D20: Km | F20: 120 | G20: 250 | H20: =F20*G20 -> 30000
C21: Mantenimiento vehicular de Dirección de Obra | D21: Km | F21: 120 | G21: 250 | H21: =F21*G21 -> 30000
C22: Pasajes para Dirección de Obra | D22: U | F22: 0 | G22: 0 | H22: =F22*G22 -> 0
C23: Gastos varios de movilidad -Estacionamiento, peajes, etc- | D23: GL | F23: 0 | G23: 1200 | H23: =F23*G23 -> 0
C24: Librería | D24: GL | F24: 0 | G24: 0 | H24: =F24*G24 -> 0
C25: Seguros para Dirección de Obra | D25: Mes | F25: 0 | G25: 18000 | H25: =F25*G25 -> 0
C26: Indumentaria y EPP para Dirección de Obra | D26: JUEGO | F26: =0.24/6 -> 0.04 | G26: 170000 | H26: =F26*G26 -> 6800
C28: Viáticos del personal operativo | D28: DIA | F28: 0 | G28: =+G18 -> 12000 | H28: =F28*G28 -> 0
C29: Alojamiento para personal operativo | D29: DIA | F29: 0 | G29: 0 | H29: =F29*G29 -> 0
C30: Combustible para movilidad de personal operativo | D30: KM | F30: 0 | G30: 0 | H30: =F30*G30 -> 0
C31: Mantenimiento vehicular para personal operativo | D31: KM | F31: 0 | G31: 0 | H31: =F31*G31 -> 0
C32: Permiso uso de vereda | D32: U | F32: 0 | G32: 60000 | H32: =F32*G32 -> 0
C33: Gastos varios de movilidad -Estacionamiento, peajes, etc- | D33: GL | F33: 0 | G33: 2000 | H33: =F33*G33 -> 0
C34: Seguros para el personal operativo | D34: MES | F34: =2*0.24 -> 0.48 | G34: 40000 | H34: =F34*G34 -> 19200
C35: Indumentaria y EPP para el personal operativo | D35: JUEGO | F35: =0.24/6 -> 0.04 | G35: 220000 | H35: =F35*G35 -> 8800
C37: Programa de Higiene y Seguridad | D37: GL | F37: 1 | G37: 0 | H37: =F37*G37 -> 0
C38: Sueldos / Honorarios de Resposable de Higiene y Seguridad | D38: GL | F38: 0 | G38: 350000 | H38: =F38*G38 -> 0
C39: Elementos de señalización | D39: GL | F39: 1 | G39: 15000 | H39: =F39*G39 -> 15000
C41: Fletes de materiales | D41: KM | F41: 1 | G41: 500000 | H41: =F41*G41 -> 500000
C42: Viáticos de chóferes | D42: DIA | F42: 0 | G42: 0 | H42: =F42*G42 -> 0
C43: Alojamiento de chóferes | D43: DIA | F43: 0 | G43: 0 | H43: =F43*G43 -> 0
C44: Combustible para movilidad de personal operativo | D44: DIA | F44: 0 | G44: 125 | H44: =F44*G44 -> 0
C45: Mantenimiento vehicular para personal de compras | D45: KM | F45: 0 | G45: 125 | H45: =F45*G45 -> 0
C46: Pasajes para personal de compras | D46: GL | F46: 0 | G46: 0 | H46: =F46*G46 -> 0
C47: Gastos varios de movilidad -Estacionamiento, peajes, etc- | D47: GL | F47: 0 | G47: 0 | H47: =F47*G47 -> 0
C48: Impuesto al cheque | D48: GL | F48: 0.006 | G48: =G12 -> 9599174.7 | H48: =F48*G48 -> 57595.048
...

Sheet Precio
A4: CLIENTE | B4: ANALISIS GENRAL DE PRECIOS POLIURETANO - PINO SOLUCIONES TECNICAS
A5: OBRA: | B5: APLICACIÓN DE ESPUMA DE POLIURETANO - MENSUAL DE PINO
A6: FECHA: | B6: 45940
A7: CONTACTO: | B7: PINO SOLUCUIONES TECNICAS
A8: ANÁLISIS DE PRECIOS
A10: RUBRO | B10: ÍTEM | C10: DENOMINACIÓN | D10: UNIDAD | E10: CANTIDAD | F10: PRECIO UNITARIO | G10: PRECIO PARCIAL
B11: 2.1. | C11: APLICACIÓN DE ESPUMA DE POLIURETANO EN TODA LA SUPERFICIE | D11: M2 | E11: =+'Análisis de precios'!E11 -> 1096 | F11: ='Análisis de precios'!G11*Cascada!#REF! -> #REF! | G11: =+E11*F11 -> #REF!
F12: TOTAL | G12: =SUM(G11:G11) -> #REF! | I12: 1113000
A13: Objeto: Provisión de materiales, herramientas, equipos y mano de obra calificada para la ejecución de trabajos de aislamiento térmico proyectado en el interior de vivienda particular.
A14: Alcance del servicio:
A15: El presente presupuesto contempla la aplicación de aislamiento térmico mediante sistema proyectado (poliuretano expandido ), considerando 2,5 cm de espesor:
A16: Lugar de obra: Vivienda particular -
A17: Importante: A la hora de la aplicación el cliente sera resonsable de retirar el cielorraso y el aislante, para de esta manera ralizar una aplicación optima.
A18: Plazo estimado de ejecución: 2 días corridos, sujeto a condiciones climáticas y logísticas favorables.
A19: Forma de pago: A la aprobacion del presupuesto se abonara el 50% del total, saldo a 30dias sin incremento.

Sheet Programa de trabajo
A4: CLIENTE | B4: ANALISIS GENRAL DE PRECIOS POLIURETANO - PINO SOLUCIONES TECNICAS
A5: OBRA: | B5: APLICACIÓN DE ESPUMA DE POLIURETANO - MENSUAL DE PINO
A6: FECHA: | B6: 45940
A7: CONTACTO: | B7: PINO SOLUCUIONES TECNICAS
A8: ANÁLISIS DE PRECIOS
A10: RUBRO | B10: ÍTEM | C10: DENOMINACIÓN | D10: UNIDAD | E10: CANTIDAD | F10: 24 DIAS
B11: 2.1. | C11: APLICACIÓN DE ESPUMA DE POLIURETANO EN TODA LA SUPERFICIE | D11: M2 | E11: =+'Análisis de precios'!E11 -> 1096

Sheet Insumos
A4: CLIENTE | B4: ANALISIS GENRAL DE PRECIOS POLIURETANO - PINO SOLUCIONES TECNICAS
A5: OBRA: | B5: APLICACIÓN DE ESPUMA DE POLIURETANO - MENSUAL DE PINO
A6: FECHA: | B6: 45940
A7: CONTACTO: | B7: PINO SOLUCUIONES TECNICAS
A8: ANÁLISIS DE PRECIOS
A10: RUBRO | B10: ÍTEM | C10: DENOMINACIÓN | D10: UNIDAD | E10: CANTIDAD | G10: PRECIO UNITARIO
A11: MO | C11: Oficial aplicador | D11: hs | E11: =SUMIF('Análisis de precios'!C10:P14,C11,'Análisis de precios'!N10:$N$14) -> 48 | F11: 7224.61 | G11: =+E11*F11 -> 346781.28
A12: MO | C12: Ayudante | D12: hs | E12: =SUMIF('Análisis de precios'!C11:P15,C12,'Análisis de precios'!N11:$N$14) -> 96 | F12: 5000 | G12: =+E12*F12 -> 480000
A13: MAT | B13: 101001 | C13: Espuma Poliuretano POLIRESINAS x kg | D13: Kg | E13: =130*17*1.2 -> 2652 | F13: =5.1*1455 -> 7420.5 | G13: =+E13*F13 -> 19679166
C14: Film polietileno negro 200 micrones (2x50 m) | D14: rollo | E14: =SUMIF('Análisis de precios'!C13:P17,C14,'Análisis de precios'!N13:$N$14) -> 0.2479638 | F14: 37000 | G14: =+E14*F14 -> 9174.6606
F15: TOTAL | G15: =SUM(G11:G14) -> 20515122

Sheet Tabla de precios por m2 y km
A1: m2 | B1: km
