Workbook

Sheet Análisis de precios
A4: CLIENTE: | B4: Ing. Slucky - ANEA INGENIEROS SA CUIT 30714427152
A5: OBRA: | B5: EDIFICIO CALLE TUCUMAN 1332
A6: FECHA: | B6: 45961
A7: CONTACTO:
A8: ANÁLISIS DE PRECIOS
A10: RUBRO | B10: ÍTEM | C10: DENOMINACIÓN | D10: UNIDAD | E10: CANTIDAD | G10: PRECIO UNITARIO | H10: PRECIO PARCIAL | I10: PRECIO RUBRO | K10: % ITEM | L10: % RUBRO | N10: Cantidad parcial | O10: Precio unitario | P10: Precio parcial
B11: 5.7. | C11: Armado y desarmado de Balancin exterior | D11: UNIDAD | E11: 4 | G11: =SUM(G12:G14) -> 193063.68 | H11: =+E11*G11 -> 772254.72 | Q11: PERSONAS | R11: DIAS TOT | S11: DIAS DE TRABAJO | T11: =+G11*E11*[1]Cascada!$H$89 -> 2089231.3
A12: MO | C12: Oficial balancinero | D12: hs | E12: 16 | F12: 6197.24 | G12: =+E12*F12 -> 99155.84 | N12: =E12*$E$11 -> 64 | O12: =F12 -> 6197.24 | P12: =N12*O12 -> 396623.36 | Q12: 2 | R12: =+N12/8 -> 8 | S12: =+R12/Q12 -> 4
A13: MO | C13: Maquinista | D13: hs | E13: 8 | F13: 6197.24 | G13: =+E13*F13 -> 49577.92 | N13: =E13*$E$11 -> 32 | O13: =F13 -> 6197.24 | P13: =N13*O13 -> 198311.68 | Q13: 1 | R13: =+N13/8 -> 4 | S13: =+R13/Q13 -> 4
A14: MO | C14: Ayudante | D14: hs | E14: 8 | F14: 5541.24 | G14: =+E14*F14 -> 44329.92 | N14: =E14*$E$11 -> 32 | O14: =F14 -> 5541.24 | P14: =N14*O14 -> 177319.68 | Q14: 1 | R14: =+N14/8 -> 4 | S14: =+R14/Q14 -> 4
B15: 5.8. | C15: Colocación De Puente De Adherencia Exterior | D15: M2 | E15: 40 | G15: =SUM(G16:G18) -> 3162.4992 | H15: =+E15*G15 -> 126499.97 | Q15: PERSONAS | R15: DIAS TOT | S15: DIAS DE TRABAJO | T15: =+G15*E15*[1]Cascada!$H$89 -> 342228.65
A16: MO | C16: Oficial balancinero | D16: hs | E16: =(8/100) -> 0.08 | F16: 6197.24 | G16: =+E16*F16 -> 495.7792 | N16: =E16*$E$15 -> 3.2 | O16: =F16 -> 6197.24 | P16: =N16*O16 -> 19831.168 | Q16: 2 | R16: =+N16/8 -> 0.4 | S16: =+R16/Q16 -> 0.2
A17: MAT | C17: Puente De Adherencia ic 52 (solido) X30 KG | D17: KG | E17: =0.3584 -> 0.3584 | F17: =250000/48 -> 5208.3333 | G17: =+E17*F17 -> 1866.6667 | N17: =E17*$E$15 -> 14.336 | O17: =F17 -> 5208.3333 | P17: =N17*O17 -> 74666.667
A18: MAT | C18: Puente De Adherencia ic 52 (liquido) X 18 KG | D18: KG | E18: 0.15361024 | F18: =250000/48 -> 5208.3333 | G18: =+E18*F18 -> 800.05333 | N18: =E18*$E$15 -> 6.1444096 | O18: =F18 -> 5208.3333 | P18: =N18*O18 -> 32002.133
B19: 5.9. | C19: Enchape Sobre Estructura De hormigón Exterior | D19: M2 | E19: 20 | G19: =SUM(G20:G25) -> 9761.7023 | H19: =+E19*G19 -> 195234.05 | Q19: PERSONAS | R19: DIAS TOT | S19: DIAS DE TRABAJO | T19: =+G19*E19*[1]Cascada!$H$89 -> 528179.45
A20: MO | C20: Oficial balancinero | D20: hs | E20: 0.412 | F20: 6197.24 | G20: =+E20*F20 -> 2553.2629 | N20: =E20*$E$19 -> 8.24 | O20: =F20 -> 6197.24 | P20: =N20*O20 -> 51065.258 | Q20: 2 | R20: =+N20/8 -> 1.03 | S20: =+R20/Q20 -> 0.515
A21: MO | C21: Maquinista | D21: hs | E21: =+E20/2 -> 0.206 | F21: 6197.24 | G21: =+E21*F21 -> 1276.6314 | N21: =E21*$E$19 -> 4.12 | O21: =F21 -> 6197.24 | P21: =N21*O21 -> 25532.629 | Q21: 1 | R21: =+N21/8 -> 0.515 | S21: =+R21/Q21 -> 0.515
A22: MO | C22: Ayudante | D22: hs | E22: =+E21 -> 0.206 | F22: 5541.24 | G22: =+E22*F22 -> 1141.4954 | N22: =E22*$E$19 -> 4.12 | O22: =F22 -> 5541.24 | P22: =N22*O22 -> 22829.909 | Q22: 1 | R22: =+N22/8 -> 0.515 | S22: =+R22/Q22 -> 0.515
A23: MAT | C23: Revoque proyectado WEBER PROMEX E 3 en 1 | D23: kg | E23: 15 | F23: 250 | G23: =+E23*F23 -> 3750 | N23: =E23*$E$19 -> 300 | O23: =F23 -> 250 | P23: =N23*O23 -> 75000
A24: MAT | C24: Malla Revoque Fibra De Vidrio 90 grs 5x5 mm (Rollo 1x50m) | D24: m2 | E24: 1 | F24: =52000/50 -> 1040 | G24: =+E24*F24 -> 1040 | N24: =E24*$E$19 -> 20 | O24: =F24 -> 1040 | P24: =N24*O24 -> 20800
A25: EQUIPOS | C25: Maquina proyectadora | D25: hs | E25: 0.0016447368 | F25: 190 | G25: =+E25*F25 -> 0.3125 | N25: =E25*$E$19 -> 0.032894737 | O25: =F25 -> 190 | P25: =N25*O25 -> 6.25
B26: 5.10. | C26: Revoque proyectado Exterior 3 en 1 | D26: M2 | E26: 400 | G26: =SUM(G27:G30) -> 15222.547 | H26: =+E26*G26 -> 6089018.9 | Q26: PERSONAS | R26: DIAS TOT | S26: DIAS DE TRABAJO | T26: =+G26*E26*[1]Cascada!$H$89 -> 16473021
A27: MO | C27: Oficial balancinero | D27: hs | E27: =+(8/25)*2 -> 0.64 | F27: 6197.24 | G27: =+E27*F27 -> 3966.2336 | N27: =E27*$E$26 -> 256 | O27: =F27 -> 6197.24 | P27: =N27*O27 -> 1586493.4 | Q27: 2 | R27: =+N27/8 -> 32 | S27: =+R27/Q27 -> 16
A28: MO | C28: Maquinista | D28: hs | E28: =+(8/25) -> 0.32 | F28: 6197.24 | G28: =+E28*F28 -> 1983.1168 | N28: =E28*$E$26 -> 128 | O28: =F28 -> 6197.24 | P28: =N28*O28 -> 793246.72 | Q28: 1 | R28: =+N28/8 -> 16 | S28: =+R28/Q28 -> 16
A29: MO | C29: Ayudante | D29: hs | E29: =+(8/25) -> 0.32 | F29: 5541.24 | G29: =+E29*F29 -> 1773.1968 | N29: =E29*$E$26 -> 128 | O29: =F29 -> 5541.24 | P29: =N29*O29 -> 709278.72 | Q29: 1 | R29: =+N29/8 -> 16 | S29: =+R29/Q29 -> 16 | U29: palets | V29: viajes de equipos
A30: MAT | C30: Revoque proyectado WEBER PROMEX E 3 en 1 | D30: kg | E30: 30 | F30: 250 | G30: =+E30*F30 -> 7500 | N30: =E30*$E$26 -> 12000 | O30: =F30 -> 250 | P30: =N30*O30 -> 3000000 | T30: =+N30/30 -> 400 | U30: =+T30/65 -> 6.1538462 | V30: =+U30/20 -> 0.30769231
B31: 5.11. | C31: Ejecucion de Mochetas exteriores | D31: M2 | E31: 16 | G31: =SUM(G32:G35) -> 32709.552 | H31: =+E31*G31 -> 523352.83 | Q31: PERSONAS | R31: DIAS TOT | S31: DIAS DE TRABAJO | T31: =+G31*E31*[1]Cascada!$H$89 -> 1415860.7
A32: MO | C32: Oficial balancinero | D32: hs | E32: 2.4 | F32: 6197.24 | G32: =+E32*F32 -> 14873.376 | N32: =E32*$E$31 -> 38.4 | O32: =F32 -> 6197.24 | P32: =N32*O32 -> 237974.02 | Q32: 2 | R32: =+N32/8 -> 4.8 | S32: =+R32/Q32 -> 2.4
A33: MO | C33: Maquinista | D33: hs | E33: =+E32/2 -> 1.2 | F33: 6197.24 | G33: =+E33*F33 -> 7436.688 | N33: =E33*$E$31 -> 19.2 | O33: =F33 -> 6197.24 | P33: =N33*O33 -> 118987.01 | Q33: 1 | R33: =+N33/8 -> 2.4 | S33: =+R33/Q33 -> 2.4
A34: MO | C34: Ayudante | D34: hs | E34: =+E33 -> 1.2 | F34: 5541.24 | G34: =+E34*F34 -> 6649.488 | N34: =E34*$E$31 -> 19.2 | O34: =F34 -> 5541.24 | P34: =N34*O34 -> 106391.81 | Q34: 1 | R34: =+N34/8 -> 2.4 | S34: =+R34/Q34 -> 2.4
A35: MAT | C35: Revoque proyectado WEBER PROMEX E 3 en 1 | D35: kg | E35: 15 | F35: 250 | G35: =+E35*F35 -> 3750 | N35: =E35*$E$31 -> 240 | O35: =F35 -> 250 | P35: =N35*O35 -> 60000
B36: 5.12. | C36: Armado y desarmado de bandejas de proteccion | D36: UNIDAD | E36: 12 | G36: =SUM(G37:G39) -> 72398.88 | H36: =+E36*G36 -> 868786.56 | Q36: PERSONAS | R36: DIAS TOT | S36: DIAS DE TRABAJO | T36: =+G36*E36*[1]Cascada!$H$89 -> 2350385.2 | U36: =SUM(T11:T36)/E26 -> 57998.267 | V36: =+U36/[1]Cascada!$H$89 -> 21438.237
A37: MO | C37: Oficial balancinero | D37: hs | E37: 6 | F37: 6197.24 | G37: =+E37*F37 -> 37183.44 | N37: =E37*$E$36 -> 72 | O37: =F37 -> 6197.24 | P37: =N37*O37 -> 446201.28 | Q37: 2 | R37: =+N37/8 -> 9 | S37: =+R37/Q37 -> 4.5 | U37: =+U36/1.21 -> 47932.452
A38: MO | C38: Maquinista | D38: hs | E38: 3 | F38: 6197.24 | G38: =+E38*F38 -> 18591.72 | N38: =E38*$E$36 -> 36 | O38: =F38 -> 6197.24 | P38: =N38*O38 -> 223100.64 | Q38: 1 | R38: =+N38/8 -> 4.5 | S38: =+R38/Q38 -> 4.5
A39: MO | C39: Ayudante | D39: hs | E39: 3 | F39: 5541.24 | G39: =+E39*F39 -> 16623.72 | N39: =E39*$E$36 -> 36 | O39: =F39 -> 5541.24 | P39: =N39*O39 -> 199484.64 | Q39: 1 | R39: =+N39/8 -> 4.5 | S39: =+R39/Q39 -> 4.5
H41: =SUM(H11:H40) -> 8575147 | P41: =SUM(P11:P40) -> 8575147

Sheet Cascada
A4: CLIENTE: | B4: =+'Análisis de precios'!B4 -> Ing. Slucky - ANEA INGENIEROS SA CUIT 30714427152
A5: OBRA: | B5: =+'Análisis de precios'!B5 -> EDIFICIO CALLE TUCUMAN 1332
A6: FECHA: | B6: =+'Análisis de precios'!B6 -> 45961
A7: CONTACTO: | B7: =+'Análisis de precios'!B7 -> 0
A8: ANÁLISIS DE PRECIOS
A10: RUBRO | B10: ITEM | C10: DENOMINACION | D10: UNIDAD | E10: CANTIDAD | F10: PRECIO UNIT SIN IVA | G10: PRECIO PARCIAL SIN IVA
A11: 1 | C11: COSTO - COSTO | G11: =SUM(G12:G14) -> 8575147
A12: 1 | B12: 1 | C12: MATERIALES | D12: GL | E12: 1 | F12: =(SUMIF('Análisis de precios'!$A$9:$A$42,"MAT",'Análisis de precios'!$P$9:$P$42)) -> 3262468.8 | G12: =+E12*F12 -> 3262468.8
A13: 1 | B13: 2 | C13: MANO DE OBRA | D13: GL | E13: 1 | F13: =SUMIF('Análisis de precios'!$A$9:$A$42,"MO",'Análisis de precios'!$P$9:$P$42) -> 5312672 | G13: =+E13*F13 -> 5312672
A14: 1 | B14: 3 | C14: EQUIPOS | D14: GL | E14: 1 | F14: =SUMIF('Análisis de precios'!$A$9:$A$42,"EQUIPOS",'Análisis de precios'!$P$9:$P$42) -> 6.25 | G14: =+E14*F14 -> 6.25
A16: 2 | C16: GASTOS GENERALES DIRECTOS | G16: =SUM(G17:G67) -> 2608649.6 | H16: =G16/G11 -> 0.30421048
C17: Sueldos / Honorarios de Dirección de Albañilería | D17: Mes | E17: 1 | F17: 1450000 | G17: =E17*F17 -> 1450000
C18: Sueldos / Honorarios de Dirección de Obra de Cielorrasos | D18: Mes | F18: 1750000 | G18: =E18*F18 -> 0
C19: Sueldos / Honorarios de Dirección de Obra de Pintura | D19: Mes | F19: 1350001 | G19: =E19*F19 -> 0
C20: Sueldos / Honorarios de Dirección de Obra de Pintura en Altura | D20: Mes | F20: 1750000 | G20: =E20*F20 -> 0
C21: Viáticos de Dirección de Obra | D21: Dia | E21: 0 | F21: 100000 | G21: =E21*F21 -> 0
C22: Alojamiento para Dirección de Obra | D22: Dia | E22: 0 | F22: 65000 | G22: =E22*F22 -> 0
C23: Combustible para movilidad de Dirección de Obra | D23: Km | E23: 300 | F23: 150 | G23: =E23*F23 -> 45000
C24: Mantenimiento vehicular de Dirección de Obra | D24: Km | E24: 300 | F24: 150 | G24: =E24*F24 -> 45000
C25: Pasajes para Dirección de Obra | D25: U | E25: 0 | F25: 1500 | G25: =E25*F25 -> 0
C26: Gastos varios de movilidad -Estacionamiento, peajes, etc- | D26: GL | E26: 30 | F26: 3000 | G26: =E26*F26 -> 90000
C27: Librería | D27: GL | E27: 0 | F27: 20000 | G27: =E27*F27 -> 0
C28: Seguros para Dirección de Obra | D28: Mes | E28: 0 | F28: 20000 | G28: =E28*F28 -> 0
C29: Indumentaria y EPP para Dirección de Obra | D29: JUEGO | E29: 0.3 | F29: 85000 | G29: =E29*F29 -> 25500
C31: Viáticos del personal operativo | D31: DIA | E31: 0 | F31: 0 | G31: =E31*F31 -> 0
C32: Alojamiento para personal operativo | D32: DIA | E32: 0 | F32: 0 | G32: =E32*F32 -> 0
C33: Combustible para movilidad de personal operativo | D33: KM | E33: 0 | F33: 0 | G33: =E33*F33 -> 0
... C37: Seguros para el personal operativo | D37: MES | E37: 0 | F37: 20000 | G37: =E37*F37 -> 0
C38: Indumentaria y EPP para el personal operativo | D38: JUEGO | E38: 2 | F38: =+(16000+16000+20000+35000)/2+2*3500+6500 -> 57000 | G38: =E38*F38 -> 114000
C40: Programa de Higiene y Seguridad | D40: GL | E40: 1 | F40: 200000 | G40: =E40*F40 -> 200000
C41: Sueldos / Honorarios de Resposable de Higiene y Seguridad | D41: GL | E41: 3 | F41: 200000 | G41: =E41*F41 -> 600000
C42: Elementos de señalización | D42: GL | E42: 0 | F42: 50000 | G42: =E42*F42 -> 0
C44: Fletes de materiales RAPIBRICK INCLUIDO EN PRECIO MATERIAL | D44: KM | F44: 0 | G44: =E44*F44 -> 0
C45: Fletes de materiales LADRILLOS | D45: KM | E45: 0 | F45: 0 | G45: =E45*F45 -> 0
C46: Fletes de materiales ARIDOS | D46: KM | E46: 0 | F46: 0 | G46: =E46*F46 -> 0
C47: Flete de materiales
C48: ALQUILER MONTACARGAS | D48: Mes | E48: 0 | F48: 130000 | G48: =E48*F48 -> 0
C49: Viáticos de chóferes | D49: DIA | E49: 0 | F49: 0 | G49: =E49*F49 -> 0
C50: Alojamiento de chóferes | D50: DIA | E50: 0 | F50: 0 | G50: =E50*F50 -> 0
C51: Combustible para movilidad de personal operativo | D51: DIA | E51: 0 | F51: =9*1100/100 -> 99 | G51: =E51*F51 -> 0
...

Sheet Precio
A4: CLIENTE: | B4: =+'Análisis de precios'!B4 -> Ing. Slucky - ANEA INGENIEROS SA CUIT 30714427152
A5: OBRA: | B5: =+'Análisis de precios'!B5 -> EDIFICIO CALLE TUCUMAN 1332
A6: FECHA: | B6: =+'Análisis de precios'!B6 -> 45961
A7: CONTACTO:
A8: ANÁLISIS DE PRECIOS
A10: RUBRO | B10: ÍTEM | C10: DENOMINACIÓN | D10: UNIDAD | E10: CANTIDAD | G10: PRECIO UNITARIO | H10: PRECIO PARCIAL | I10: PRECIO RUBRO | K10: % ITEM | L10: % RUBRO
A11: 5. | B11: 1 | C11: REVOQUE EXTERIOR EN ALTURA | I11: =SUM(H12:H17) -> 17584843 | L11: =+I11/I19 -> 1 | M11: =+I11/E23 -> 43962.107
B12: 1.1 | C12: =+'Análisis de precios'!C11 -> Armado y desarmado de Balancin exterior | D12: =+'Análisis de precios'!D11 -> UNIDAD | E12: =+'Análisis de precios'!E11 -> 4 | G12: =+'Análisis de precios'!G11*Cascada!H90/1.21 -> 395910.93 | H12: =+E12*G12 -> 1583643.7 | K12: =+H12/$I$19 -> 0.090057316
B13: 1.2 | C13: =+'Análisis de precios'!C15 -> Colocación De Puente De Adherencia Exterior | D13: =+'Análisis de precios'!D15 -> M2 | E13: =+'Análisis de precios'!E15 -> 40 | G13: =+'Análisis de precios'!G15*Cascada!H90/1.21 -> 6485.2592 | H13: =+E13*G13 -> 259410.37 | K13: =+H13/$I$19 -> 0.01475193
B14: 1.3 | C14: =+'Análisis de precios'!C19 -> Enchape Sobre Estructura De hormigón Exterior | D14: =+'Análisis de precios'!D19 -> M2 | E14: =+'Análisis de precios'!E19 -> 20 | G14: =+'Análisis de precios'!G19*Cascada!H90/1.21 -> 20018.082 | H14: =+E14*G14 -> 400361.65 | K14: =+H14/$I$19 -> 0.022767428
B15: 1.4 | C15: =+'Análisis de precios'!C26 -> Revoque proyectado Exterior 3 en 1 | D15: =+'Análisis de precios'!D26 -> M2 | E15: =+'Análisis de precios'!E26 -> 400 | G15: =+'Análisis de precios'!G26*Cascada!H90/1.21 -> 31216.502 | H15: =+E15*G15 -> 12486601 | K15: =+H15/$I$19 -> 0.71007749
B16: 1.5 | C16: =+'Análisis de precios'!C31 -> Ejecucion de Mochetas exteriores | D16: =+'Análisis de precios'!D31 -> M2 | E16: =+'Análisis de precios'!E31 -> 16 | G16: =+'Análisis de precios'!G31*Cascada!H90/1.21 -> 67076.672 | H16: =+E16*G16 -> 1073226.8 | K16: =+H16/$I$19 -> 0.061031354
B17: 1.6 | C17: =+'Análisis de precios'!C36 -> Armado y desarmado de bandejas de proteccion | D17: =+'Análisis de precios'!D36 -> UNIDAD | E17: =+'Análisis de precios'!E36 -> 12 | G17: =+'Análisis de precios'!G36*Cascada!H90/1.21 -> 148466.6 | H17: =+E17*G17 -> 1781599.2 | K17: =+H17/$I$19 -> 0.10131448
H19: PRECIO TOTAL IVA NO INCLUIDO | I19: =SUM(I11:I18) -> 17584843 | K19: =+I19*1.21 -> 21277660
A21: RUBRO | B21: ÍTEM | C21: DENOMINACIÓN | D21: UNIDAD | E21: CANTIDAD | G21: PRECIO UNITARIO | H21: PRECIO PARCIAL | I21: PRECIO RUBRO | K21: % ITEM | L21: % RUBRO
A22: 5. | B22: 1 | C22: REVOQUE EXTERIOR EN ALTURA | I22: =SUM(H23:H28) -> 17584843 | L22: =+I22/I25 -> 1
B23: 1.1 | C23: =+C15 -> Revoque proyectado Exterior 3 en 1 | D23: =+D15 -> M2 | E23: =+E15 -> 400 | F23: =+F15 -> 0 | G23: =+M11 -> 43962.107 | H23: =+E23*G23 -> 17584843 | K23: =+H23/$I$25 -> 1
H25: PRECIO TOTAL IVA NO INCLUIDO | I25: =SUM(I22:I24) -> 17584843 | K25: =+I25*1.21 -> 21277660
B27: PLAZO DE OBRA: 3 MESES
B28: FORMA DE PAGO:
B29: SE ESTABLECE UN ANTICIPO FINANCIERO DEL 30% AL INICIO DE OBRA.
B30: EL SALDO RESTANTE SE ABONARÁ MEDIANTE CERTIFICACIONES MENSUALES
B31: FORMA DE ACTUALIZACION: MEDIANTE INDICES CAC - MES BASE SEPTIEMBRE 2025

Sheet Programa de trabajo
A4: CLIENTE: | B4: =+'Análisis de precios'!B4 -> Ing. Slucky - ANEA INGENIEROS SA CUIT 30714427152
A5: OBRA: | B5: =+'Análisis de precios'!B5 -> EDIFICIO CALLE TUCUMAN 1332
A6: FECHA: | B6: =+'Análisis de precios'!B6 -> 45961
A7: CONTACTO: | B7: =+'Análisis de precios'!B7 -> 0
A8: ANÁLISIS DE PRECIOS
A10: RUBRO | B10: ÍTEM | C10: DENOMINACIÓN | D10: UNIDAD | E10: CANTIDAD | F10: SEMANA 1 | G10: SEMANA 2 | H10: SEMANA 3
B11: 1.1 | C11: TOTALIDAD DE LOS TRABAJOS | D11: GL | E11: 1

Sheet Insumos
A4: CLIENTE: | B4: Ing. Slucky - ANEA INGENIEROS SA CUIT 30714427152
A5: OBRA: | B5: EDIFICIO CALLE TUCUMAN 1332
A6: FECHA: | B6: 45961
A7: CONTACTO:
A8: ANÁLISIS DE PRECIOS
A10: RUBRO | B10: ÍTEM | C10: DENOMINACIÓN | D10: UNIDAD | E10: CANTIDAD | G10: PRECIO UNITARIO | H10: PERSONAS | I10: DIAS TOT | J10: DIAS DE TRABAJO
A11: MO | C11: Oficial balancinero | D11: hs | E11: =SUMIF('Análisis de precios'!C10:$P$39,C11,'Análisis de precios'!N10:$N$39) -> 441.84 | F11: 6197.24 | G11: =+E11*F11 -> 2738188.5 | H11: 2 | I11: =+E11/8 -> 55.23 | J11: =+I11/H11 -> 27.615
A12: MO | C12: Maquinista | D12: hs | E12: =SUMIF('Análisis de precios'!C11:$P$39,C12,'Análisis de precios'!N11:$N$39) -> 219.32 | F12: 6197.24 | G12: =+E12*F12 -> 1359178.7 | H12: 1 | I12: =+E12/8 -> 27.415 | J12: =+I12/H12 -> 27.415
A13: MO | C13: Ayudante | D13: hs | E13: =SUMIF('Análisis de precios'!C12:$P$39,C13,'Análisis de precios'!N12:$N$39) -> 219.32 | F13: 5541.24 | G13: =+E13*F13 -> 1215304.8 | H13: 1 | I13: =+E13/8 -> 27.415 | J13: =+I13/H13 -> 27.415
A14: MAT | C14: Puente De Adherencia ic 52 (solido) X30 KG | D14: KG | E14: =SUMIF('Análisis de precios'!C13:$P$39,C14,'Análisis de precios'!N13:$N$39) -> 14.336 | F14: =250000/48 -> 5208.3333 | G14: =+E14*F14 -> 74666.667
A15: MAT | C15: Puente De Adherencia ic 52 (liquido) X 18 KG | D15: KG | E15: =SUMIF('Análisis de precios'!C14:$P$39,C15,'Análisis de precios'!N14:$N$39) -> 6.1444096 | F15: =250000/48 -> 5208.3333 | G15: =+E15*F15 -> 32002.133
A16: MAT | C16: Revoque proyectado WEBER PROMEX E 3 en 1 | D16: kg | E16: =SUMIF('Análisis de precios'!C15:$P$39,C16,'Análisis de precios'!N15:$N$39) -> 12540 | F16: 250 | G16: =+E16*F16 -> 3135000
A17: MAT | C17: Malla Revoque Fibra De Vidrio 90 grs 5x5 mm (Rollo 1x50m) | D17: m2 | E17: =SUMIF('Análisis de precios'!C16:$P$39,C17,'Análisis de precios'!N16:$N$39) -> 20 | F17: =52000/50 -> 1040 | G17: =+E17*F17 -> 20800
A18: EQUIPOS | C18: Maquina proyectadora | D18: hs | E18: =SUMIF('Análisis de precios'!C17:$P$39,C18,'Análisis de precios'!N17:$N$39) -> 0.032894737 | F18: 190 | G18: =+E18*F18 -> 6.25
G20: =SUM(G11:G19) -> 8575147
